Workbook

Sheet All Results
A1: Register No | B1: Year | C1: Dept | D1: Scheme | E1: Subject | F1: Subject Name | G1: Grade | H1: SGPA
A2: BMC20CS029 | B2: 2020 | C2: CS | D2: 2019 | E2: CST306 | F2: CST306 | G2: F | H2: 0
A3: BMC20CS044 | B3: 2020 | C3: CS | D3: 2019 | E3: CST302 | F3: CST302 | G3: F | H3: 0
A4: BMC20CS049 | B4: 2020 | C4: CS | D4: 2019 | E4: CST304 | F4: CST304 | G4: P | H4: 5.5
A5: BMC20CS053 | B5: 2020 | C5: CS | D5: 2019 | E5: CST362 | F5: PROGRAMMING IN | G5: F | H5: 0
A6: BMC20CS055 | B6: 2020 | C6: CS | D6: 2019 | E6: CST362 | F6: PROGRAMMING IN | G6: P | H6: 5.5
A7: BMC20CS056 | B7: 2020 | C7: CS | D7: 2019 | E7: CST304 | F7: CST304 | G7: ABSENT | H7: 0
A8: BMC20CS056 | B8: 2020 | C8: CS | D8: 2019 | E8: CST306 | F8: CST306 | G8: ABSENT | H8: 0
A9: BMC20CS056 | B9: 2020 | C9: CS | D9: 2019 | E9: CST362 | F9: PROGRAMMING IN | G9: ABSENT | H9: 0
A10: BMC22CS001 | B10: 2022 | C10: CS | D10: 2019 | E10: HUT300 | F10: INDUSTRIAL | G10: F | H10: 0
A11: BMC22CS001 | B11: 2022 | C11: CS | D11: 2019 | E11: CST306 | F11: CST306 | G11: P | H11: 0
A12: BMC22CS005 | B12: 2022 | C12: CS | D12: 2019 | E12: HUT300 | F12: INDUSTRIAL | G12: ABSENT | H12: 0
A13: BMC22CS005 | B13: 2022 | C13: CS | D13: 2019 | E13: CST308 | F13: COMPREHENSIVE | G13: ABSENT | H13: 0
... A282: BMC22ME019 | B282: 2022 | C282: ME | D282: 2019 | E282: MET304 | F282: MET304 | G282: ABSENT | H282: 0

Sheet OVERALL SUMMARY
A1: KTU RESULT ANALYZER - OVERALL SUMMARY REPORT
A2: BASELIOS MATHEWS II COLLEGE OF ENGINEERING
A3: B.Tech S6 (S, FE) Exam Dec 2025 (2019 Scheme) (S6 Result)
A5: OVERALL STATISTICS - REGULAR STUDENTS ONLY
A6: Total Reg Students | B6: Total Passed | C6: Total Failed | D6: Overall Pass % | E6: Overall Fail %
A7: 88 | B7: 13 | C7: 75 | D7: 14.772727 | E7: 85.227273
A11: DEPARTMENT-WISE PERFORMANCE ANALYSIS
A12: Department Name | B12: Total Regular Students | C12: Total Pass | D12: Total Fail | E12: Pass % | F12: Fail %
A13: CE | B13: 7 | C13: 1 | D13: 6 | E13: 14.285714 | F13: 85.714286
A14: CS | B14: 48 | C14: 11 | D14: 37 | E14: 22.916667 | F14: 77.083333
A15: EC | B15: 7 | C15: 0 | D15: 7 | E15: 0 | F15: 100
A16: EE | B16: 10 | C16: 1 | D16: 9 | E16: 10 | F16: 90
A17: ME | B17: 16 | C17: 0 | D17: 16 | E17: 0 | F17: 100
A20: TOP 5 PERFORMING SUBJECTS
A21: Rank | B21: Subject Code | C21: Department | D21: Pass % | E21: Fail % | F21: Total Students | G21: Pass | H21: Fail
A22: 1 | B22: CST304 | C22: CS | D22: 60 | E22: 40 | F22: 10 | G22: 6 | H22: 4
A23: 2 | B23: CST308 | C23: CS | D23: 38.461538 | E23: 61.538462 | F23: 26 | G23: 10 | H23: 16
A24: 3 | B24: HUT300 | C24: CS | D24: 26.829268 | E24: 73.170732 | F24: 41 | G24: 11 | H24: 30
A25: 4 | B25: CST302 | C25: CS | D25: 21.052632 | E25: 78.947368 | F25: 19 | G25: 4 | H25: 15
A26: 5 | B26: EET308 | C26: EE | D26: 20 | E26: 80 | F26: 10 | G26: 2 | H26: 8
A29: BOTTOM 5 PERFORMING SUBJECTS (NEEDS ATTENTION)
A30: Rank | B30: Subject Code | C30: Department | D30: Pass % | E30: Fail % | F30: Total Students | G30: Pass | H30: Fail
A31: 1 | B31: MET308 | C31: ME | D31: 0 | E31: 100 | F31: 10 | G31: 0 | H31: 10
A32: 2 | B32: MET302 | C32: ME | D32: 9.0909091 | E32: 90.909091 | F32: 11 | G32: 1 | H32: 10
A33: 3 | B33: MET312 | C33: ME | D33: 10 | E33: 90 | F33: 10 | G33: 1 | H33: 9
A34: 4 | B34: CST372 | C34: CS | D34: 14.285714 | E34: 85.714286 | F34: 14 | G34: 2 | H34: 12
A35: 5 | B35: EET308 | C35: EE | D35: 20 | E35: 80 | F35: 10 | G35: 2 | H35: 8

Sheet CE
A1: KTU RESULT ANALYZER
A2: BASELIOS MATHEWS II COLLEGE OF ENGINEERING
A3: B.Tech S6 (S, FE) Exam Dec 2025 (2019 Scheme) (S6 Result)
A4: Department: CE
A5: 📊 Overall Stats: 12 Students | 7 Regular | 5 Backlog
A7: SUBJECT ANALYTICS DASHBOARD
A8: Select Subject: | B8: Department
B10: Appeared | D10: Passed | G10: Failed | I10: Pass Rate | K10: Fail Rate
B11: =IFERROR(VLOOKUP("CE_" & UPPER($B$8), _DATA_!$A$2:$AZ$38, 2, FALSE), 0) -> 0 | D11: =IFERROR(VLOOKUP("CE_" & UPPER($B$8), _DATA_!$A$2:$AZ$38, 3, FALSE), 0) -> 0 | G11: =IFERROR(VLOOKUP("CE_" & UPPER($B$8), _DATA_!$A$2:$AZ$38, 4, FALSE), 0) -> 0 | I11: =IFERROR(VLOOKUP("CE_" & UPPER($B$8), _DATA_!$A$2:$AZ$38, 5, FALSE), 0) -> 0 | K11: =IFERROR(VLOOKUP("CE_" & UPPER($B$8), _DATA_!$A$2:$AZ$38, 6, FALSE), 0) -> 0
A32: BATCH - 2020
A33: Register No | B33: CET302 | C33: CET304 | D33: CET306 | E33: HUT300 | F33: Arrears | G33: SGPA
A34: BMC20CE010 | B34: P | C34: - | D34: - | E34: - | F34: 0 | G34: 5.5
A35: BMC20CE035 | B35: F | C35: F | D35: P | E35: F | F35: 3 | G35: 0
A40: BATCH - 2021
A41: Register No | B41: CET302 | C41: CET304 | D41: CET306 | E41: CET352 | F41: HUT300 | G41: Arrears | H41: SGPA
A42: BMC21CE003 | B42: ABSENT | C42: F | D42: - | E42: - | F42: - | G42: 2 | H42: 0
A43: BMC21CE008 | B43: ABSENT | C43: - | D43: C | E43: - | F43: ABSENT | G43: 2 | H43: 0
A44: BMC21CE012 | B44: ABSENT | C44: - | D44: - | E44: ABSENT | F44: F | G44: 3 | H44: 0
A49: BATCH - 2022
A50: Register No | B50: CET306 | C50: CET308 | D50: CET352 | E50: HUT300 | F50: Arrears | G50: SGPA
A51: BMC22CE001 | B51: - | C51: - | D51: - | E51: F | F51: 1 | G51: 0
A52: BMC22CE004 | B52: - | C52: F | D52: - | E52: - | F52: 1 | G52: 0
A53: BMC22CE005 | B53: - | C53: F | D53: - | E53: - | F53: 1 | G53: 0
A54: BMC22CE008 | B54: - | C54: P | D54: - | E54: F | F54: 1 | G54: 0
A55: BMC22CE010 | B55: ABSENT | C55: - | D55: - | E55: P | F55: 1 | G55: 0
A56: BMC22CE011 | B56: - | C56: P | D56: P | E56: C | F56: 0 | G56: 5.93
A57: BMC22CE013 | B57: ABSENT | C57: - | D57: - | E57: - | F57: 1 | G57: 0
A62: DEPARTMENT PERFORMANCE ANALYSIS (BATCH 2022)
A63: Batch | B63: Total Students | C63: Total Pass | D63: Total Fail | E63: Pass % | F63: Fail %
A64: 2022 | B64: 7 | C64: 1 | D64: 6 | E64: 14.285714 | F64: 85.714286
A68: SUBJECT-WISE ANALYSIS (BATCH - 2022)
A69: SubCode | B69: Subject Name | C69: Pass% | D69: Fail% | E69: Pass | F69: Fail | G69: S | H69: A+ | I69: A | J69: B+ | K69: B | L69: C+ | M69: C | N69: D | O69: P | P69: F | Q69: FE | R69: Absent | S69: Withheld
A70: CET306 | B70: DESIGN OF | C70: 0 | D70: 100 | E70: 0 | F70: 2 | G70: 0 | H70: 0 | I70: 0 | J70: 0 | K70: 0 | L70: 0 | M70: 0 | N70: 0 | O70: 0 | P70: 0 | Q70: 0 | R70: 2 | S70: 0
A71: CET308 | B71: CET308 | C71: 50 | D71: 50 | E71: 2 | F71: 2 | G71: 0 | H71: 0 | I71: 0 | J71: 0 | K71: 0 | L71: 0 | M71: 0 | N71: 0 | O71: 2 | P71: 2 | Q71: 0 | R71: 0 | S71: 0
A72: CET352 | B72: CET352 | C72: 100 | D72: 0 | E72: 1 | F72: 0 | G72: 0 | H72: 0 | I72: 0 | J72: 0 | K72: 0 | L72: 0 | M72: 0 | N72: 0 | O72: 1 | P72: 0 | Q72: 0 | R72: 0 | S72: 0
A73: HUT300 | B73: INDUSTRIAL | C73: 50 | D73: 50 | E73: 2 | F73: 2 | G73: 0 | H73: 0 | I73: 0 | J73: 0 | K73: 0 | L73: 0 | M73: 1 | N73: 0 | O73: 1 | P73: 2 | Q73: 0 | R73: 0 | S73: 0
AZ501: ="CE_" & UPPER($B$8) -> 0
AZ506: ="S - " & TEXT($BA$506/MAX($BA$521, 1), "0%") -> 0 | BA506: =IFERROR(VLOOKUP($AZ$501, _DATA_!$A$2:$AZ$38, 7, FALSE), 0) -> 0
AZ507: ="A+ - " & TEXT($BA$507/MAX($BA$521, 1), "0%") -> 0 | BA507: =IFERROR(VLOOKUP($AZ$501, _DATA_!$A$2:$AZ$38, 8, FALSE), 0) -> 0
AZ508: ="A - " & TEXT($BA$508/MAX($BA$521, 1), "0%") -> 0 | BA508: =IFERROR(VLOOKUP($AZ$501, _DATA_!$A$2:$AZ$38, 9, FALSE), 0) -> 0
...

Sheet CS
A1: KTU RESULT ANALYZER
A2: BASELIOS MATHEWS II COLLEGE OF ENGINEERING
A3: B.Tech S6 (S, FE) Exam Dec 2025 (2019 Scheme) (S6 Result)
A4: Department: CS
A5: 📊 Overall Stats: 54 Students | 48 Regular | 6 Backlog
A7: SUBJECT ANALYTICS DASHBOARD
A8: Select Subject: | B8: Department
B10: Appeared | D10: Passed | G10: Failed | I10: Pass Rate | K10: Fail Rate
B11: =IFERROR(VLOOKUP("CS_" & UPPER($B$8), _DATA_!$A$2:$AZ$38, 2, FALSE), 0) -> 0 | D11: =IFERROR(VLOOKUP("CS_" & UPPER($B$8), _DATA_!$A$2:$AZ$38, 3, FALSE), 0) -> 0 | G11: =IFERROR(VLOOKUP("CS_" & UPPER($B$8), _DATA_!$A$2:$AZ$38, 4, FALSE), 0) -> 0 | I11: =IFERROR(VLOOKUP("CS_" & UPPER($B$8), _DATA_!$A$2:$AZ$38, 5, FALSE), 0) -> 0 | K11: =IFERROR(VLOOKUP("CS_" & UPPER($B$8), _DATA_!$A$2:$AZ$38, 6, FALSE), 0) -> 0
A32: BATCH - 2020
A33: Register No | B33: CST302 | C33: CST304 | D33: CST306 | E33: CST362 | F33: Arrears | G33: SGPA
A34: BMC20CS029 | B34: - | C34: - | D34: F | E34: - | F34: 1 | G34: 0
A35: BMC20CS044 | B35: F | C35: - | D35: - | E35: - | F35: 1 | G35: 0
A36: BMC20CS049 | B36: - | C36: P | D36: - | E36: - | F36: 0 | G36: 5.5
A37: BMC20CS053 | B37: - | C37: - | D37: - | E37: F | F37: 1 | G37: 0
A38: BMC20CS055 | B38: - | C38: - | D38: - | E38: P | F38: 0 | G38: 5.5
A39: BMC20CS056 | B39: - | C39: ABSENT | D39: ABSENT | E39: ABSENT | F39: 3 | G39: 0
A44: BATCH - 2022
A45: Register No | B45: CST302 | C45: CST304 | D45: CST306 | E45: CST308 | F45: CST372 | G45: HUT300 | H45: Arrears | I45: SGPA
A46: BMC22CS001 | B46: - | C46: - | D46: P | E46: - | F46: - | G46: F | H46: 1 | I46: 0
A47: BMC22CS005 | B47: - | C47: - | D47: - | E47: ABSENT | F47: ABSENT | G47: ABSENT | H47: 3 | I47: 0
A48: BMC22CS006 | B48: - | C48: - | D48: - | E48: F | F48: - | G48: F | H48: 2 | I48: 0
A49: BMC22CS009 | B49: F | C49: - | D49: F | E49: - | F49: - | G49: F | H49: 3 | I49: 0
A50: BMC22CS011 | B50: F | C50: - | D50: - | E50: - | F50: - | G50: F | H50: 2 | I50: 0
A51: BMC22CS012 | B51: P | C51: - | D51: - | E51: - | F51: P | G51: P | H51: 0 | I51: 5.5
A52: BMC22CS014 | B52: - | C52: - | D52: - | E52: F | F52: - | G52: - | H52: 1 | I52: 0
A53: BMC22CS015 | B53: - | C53: - | D53: - | E53: P | F53: - | G53: - | H53: 0 | I53: 5.5
A54: BMC22CS016 | B54: F | C54: - | D54: - | E54: - | F54: - | G54: F | H54: 2 | I54: 0
A55: BMC22CS017 | B55: F | C55: - | D55: ABSENT | E55: - | F55: P | G55: F | H55: 3 | I55: 0
A56: BMC22CS022 | B56: - | C56: F | D56: - | E56: - | F56: - | G56: F | H56: 2 | I56: 0
A57: BMC22CS023 | B57: - | C57: F | D57: - | E57: - | F57: - | G57: F | H57: 2 | I57: 0
... A93: BMC22CS119 | B93: - | C93: - | D93: - | E93: C+ | F93: - | G93: D | H93: 0 | I93: 6.25
A98: DEPARTMENT PERFORMANCE ANALYSIS (BATCH 2022)
A99: Batch | B99: Total Students | C99: Total Pass | D99: Total Fail | E99: Pass % | F99: Fail %
A100: 2022 | B100: 48 | C100: 11 | D100: 37 | E100: 22.916667 | F100: 77.083333
A104: SUBJECT-WISE ANALYSIS (BATCH - 2022)
A105: SubCode | B105: Subject Name | C105: Pass% | D105: Fail% | E105: Pass | F105: Fail | G105: S | H105: A+ | I105: A | J105: B+ | K105: B | L105: C+ | M105: C | N105: D | O105: P | P105: F | Q105: FE | R105: Absent | S105: Withheld
A106: CST302 | B106: CST302 | C106: 21.052632 | D106: 78.947368 | E106: 4 | F106: 15 | G106: 0 | H106: 0 | I106: 0 | J106: 0 | K106: 0 | L106: 0 | M106: 2 | N106: 0 | O106: 2 | P106: 11 | Q106: 0 | R106: 3 | S106: 1
A107: CST304 | B107: CST304 | C107: 60 | D107: 40 | E107: 6 | F107: 4 | G107: 0 | H107: 0 | I107: 0 | J107: 0 | K107: 1 | L107: 1 | M107: 0 | N107: 3 | O107: 1 | P107: 2 | Q107: 0 | R107: 1 | S107: 1
A108: CST306 | B108: CST306 | C108: 14.285714 | D108: 85.714286 | E108: 1 | F108: 6 | G108: 0 | H108: 0 | I108: 0 | J108: 0 | K108: 0 | L108: 0 | M108: 0 | N108: 0 | O108: 1 | P108: 2 | Q108: 0 | R108: 3 | S108: 1
...

Sheet EC
A1: KTU RESULT ANALYZER
A2: BASELIOS MATHEWS II COLLEGE OF ENGINEERING
A3: B.Tech S6 (S, FE) Exam Dec 2025 (2019 Scheme) (S6 Result)
A4: Department: EC
A5: 📊 Overall Stats: 9 Students | 7 Regular | 2 Backlog
A7: SUBJECT ANALYTICS DASHBOARD
A8: Select Subject: | B8: Department
B10: Appeared | D10: Passed | G10: Failed | I10: Pass Rate | K10: Fail Rate
B11: =IFERROR(VLOOKUP("EC_" & UPPER($B$8), _DATA_!$A$2:$AZ$38, 2, FALSE), 0) -> 0 | D11: =IFERROR(VLOOKUP("EC_" & UPPER($B$8), _DATA_!$A$2:$AZ$38, 3, FALSE), 0) -> 0 | G11: =IFERROR(VLOOKUP("EC_" & UPPER($B$8), _DATA_!$A$2:$AZ$38, 4, FALSE), 0) -> 0 | I11: =IFERROR(VLOOKUP("EC_" & UPPER($B$8), _DATA_!$A$2:$AZ$38, 5, FALSE), 0) -> 0 | K11: =IFERROR(VLOOKUP("EC_" & UPPER($B$8), _DATA_!$A$2:$AZ$38, 6, FALSE), 0) -> 0
A32: BATCH - 2019
A33: Register No | B33: ECT302 | C33: ECT304 | D33: Arrears | E33: SGPA
A34: BMC19EC002 | B34: ABSENT | C34: ABSENT | D34: 2 | E34: 0
A39: BATCH - 2021
A40: Register No | B40: ECT304 | C40: Arrears | D40: SGPA
A41: BMC21EC003 | B41: F | C41: 1 | D41: 0
A46: BATCH - 2022
A47: Register No | B47: ECT302 | C47: ECT304 | D47: ECT306 | E47: ECT308 | F47: ECT362 | G47: HUT310 | H47: Arrears | I47: SGPA
A48: BMC22EC001 | B48: - | C48: - | D48: ABSENT | E48: - | F48: F | G48: F | H48: 3 | I48: 0
A49: BMC22EC002 | B49: - | C49: F | D49: ABSENT | E49: - | F49: F | G49: ABSENT | H49: 4 | I49: 0
A50: BMC22EC010 | B50: - | C50: - | D50: ABSENT | E50: F | F50: F | G50: F | H50: 4 | I50: 0
A51: BMC22EC013 | B51: - | C51: F | D51: - | E51: - | F51: F | G51: F | H51: 3 | I51: 0
A52: BMC22EC015 | B52: F | C52: C | D52: - | E52: - | F52: F | G52: - | H52: 2 | I52: 0
A53: LBMC22EC020 | B53: F | C53: - | D53: - | E53: - | F53: - | G53: - | H53: 1 | I53: 0
A54: LBMC22EC021 | B54: - | C54: - | D54: - | E54: - | F54: F | G54: - | H54: 1 | I54: 0
A59: DEPARTMENT PERFORMANCE ANALYSIS (BATCH 2022)
A60: Batch | B60: Total Students | C60: Total Pass | D60: Total Fail | E60: Pass % | F60: Fail %
A61: 2022 | B61: 7 | C61: 0 | D61: 7 | E61: 0 | F61: 100
A65: SUBJECT-WISE ANALYSIS (BATCH - 2022)
A66: SubCode | B66: Subject Name | C66: Pass% | D66: Fail% | E66: Pass | F66: Fail | G66: S | H66: A+ | I66: A | J66: B+ | K66: B | L66: C+ | M66: C | N66: D | O66: P | P66: F | Q66: FE | R66: Absent | S66: Withheld
A67: ECT302 | B67: ELECTROMAGNETICS | C67: 0 | D67: 100 | E67: 0 | F67: 2 | G67: 0 | H67: 0 | I67: 0 | J67: 0 | K67: 0 | L67: 0 | M67: 0 | N67: 0 | O67: 0 | P67: 2 | Q67: 0 | R67: 0 | S67: 0
A68: ECT304 | B68: VLSI CIRCUIT | C68: 33.333333 | D68: 66.666667 | E68: 1 | F68: 2 | G68: 0 | H68: 0 | I68: 0 | J68: 0 | K68: 0 | L68: 0 | M68: 1 | N68: 0 | O68: 0 | P68: 2 | Q68: 0 | R68: 0 | S68: 0
A69: ECT306 | B69: INFORMATION | C69: 0 | D69: 100 | E69: 0 | F69: 3 | G69: 0 | H69: 0 | I69: 0 | J69: 0 | K69: 0 | L69: 0 | M69: 0 | N69: 0 | O69: 0 | P69: 0 | Q69: 0 | R69: 3 | S69: 0
A70: ECT308 | B70: COMPREHENSIVE | C70: 0 | D70: 100 | E70: 0 | F70: 1 | G70: 0 | H70: 0 | I70: 0 | J70: 0 | K70: 0 | L70: 0 | M70: 0 | N70: 0 | O70: 0 | P70: 1 | Q70: 0 | R70: 0 | S70: 0
A71: ECT362 | B71: INTRODUCTION TO MEMS | C71: 0 | D71: 100 | E71: 0 | F71: 6 | G71: 0 | H71: 0 | I71: 0 | J71: 0 | K71: 0 | L71: 0 | M71: 0 | N71: 0 | O71: 0 | P71: 6 | Q71: 0 | R71: 0 | S71: 0
A72: HUT310 | B72: MANAGEMENT FOR | C72: 0 | D72: 100 | E72: 0 | F72: 4 | G72: 0 | H72: 0 | I72: 0 | J72: 0 | K72: 0 | L72: 0 | M72: 0 | N72: 0 | O72: 0 | P72: 3 | Q72: 0 | R72: 1 | S72: 0
AZ501: ="EC_" & UPPER($B$8) -> 0
AZ506: ="S - " & TEXT($BA$506/MAX($BA$521, 1), "0%") -> 0 | BA506: =IFERROR(VLOOKUP($AZ$501, _DATA_!$A$2:$AZ$38, 7, FALSE), 0) -> 0
AZ507: ="A+ - " & TEXT($BA$507/MAX($BA$521, 1), "0%") -> 0 | BA507: =IFERROR(VLOOKUP($AZ$501, _DATA_!$A$2:$AZ$38, 8, FALSE), 0) -> 0
AZ508: ="A - " & TEXT($BA$508/MAX($BA$521, 1), "0%") -> 0 | BA508: =IFERROR(VLOOKUP($AZ$501, _DATA_!$A$2:$AZ$38, 9, FALSE), 0) -> 0
AZ509: ="B+ - " & TEXT($BA$509/MAX($BA$521, 1), "0%") -> 0 | BA509: =IFERROR(VLOOKUP($AZ$501, _DATA_!$A$2:$AZ$38, 10, FALSE), 0) -> 0
...

Sheet EE
A1: KTU RESULT ANALYZER
A2: BASELIOS MATHEWS II COLLEGE OF ENGINEERING
A3: B.Tech S6 (S, FE) Exam Dec 2025 (2019 Scheme) (S6 Result)
A4: Department: EE
A5: 📊 Overall Stats: 16 Students | 10 Regular | 6 Backlog
A7: SUBJECT ANALYTICS DASHBOARD
A8: Select Subject: | B8: Department
B10: Appeared | D10: Passed | G10: Failed | I10: Pass Rate | K10: Fail Rate
B11: =IFERROR(VLOOKUP("EE_" & UPPER($B$8), _DATA_!$A$2:$AZ$38, 2, FALSE), 0) -> 0 | D11: =IFERROR(VLOOKUP("EE_" & UPPER($B$8), _DATA_!$A$2:$AZ$38, 3, FALSE), 0) -> 0 | G11: =IFERROR(VLOOKUP("EE_" & UPPER($B$8), _DATA_!$A$2:$AZ$38, 4, FALSE), 0) -> 0 | I11: =IFERROR(VLOOKUP("EE_" & UPPER($B$8), _DATA_!$A$2:$AZ$38, 5, FALSE), 0) -> 0 | K11: =IFERROR(VLOOKUP("EE_" & UPPER($B$8), _DATA_!$A$2:$AZ$38, 6, FALSE), 0) -> 0
A32: BATCH - 2019
A33: Register No | B33: EET302 | C33: EET304 | D33: EET312 | E33: Arrears | F33: SGPA
A34: BMC19EE004 | B34: - | C34: F | D34: - | E34: 1 | F34: 0
A35: BMC19EE009 | B35: F | C35: F | D35: F | E35: 3 | F35: 0
A40: BATCH - 2020
A41: Register No | B41: EET302 | C41: EET304 | D41: EET306 | E41: Arrears | F41: SGPA
A42: BMC20EE011 | B42: F | C42: F | D42: P | E42: 2 | F42: 0
A47: BATCH - 2021
A48: Register No | B48: EET302 | C48: EET304 | D48: Arrears | E48: SGPA
A49: BMC21EE004 | B49: F | C49: F | D49: 2 | E49: 0
A50: BMC21EE025 | B50: F | C50: F | D50: 2 | E50: 0
A51: BMC21EE028 | B51: - | C51: F | D51: 1 | E51: 0
A56: BATCH - 2022
A57: Register No | B57: EEL334 | C57: EET302 | D57: EET304 | E57: EET306 | F57: EET308 | G57: HUT310 | H57: Arrears | I57: SGPA
A58: BMC22EE001 | B58: - | C58: F | D58: F | E58: F | F58: F | G58: - | H58: 4 | I58: 0
A59: BMC22EE002 | B59: - | C59: - | D59: - | E59: D | F59: P | G59: - | H59: 0 | I59: 5.9
A60: BMC22EE003 | B60: - | C60: F | D60: F | E60: F | F60: F | G60: - | H60: 4 | I60: 0
A61: BMC22EE004 | B61: - | C61: - | D61: - | E61: P | F61: F | G61: F | H61: 2 | I61: 0
A62: BMC22EE005 | B62: P | C62: P | D62: ABSENT | E62: F | F62: F | G62: ABSENT | H62: 4 | I62: 0
A63: BMC22EE007 | B63: - | C63: F | D63: F | E63: ABSENT | F63: F | G63: - | H63: 4 | I63: 0
A64: BMC22EE008 | B64: - | C64: ABSENT | D64: F | E64: F | F64: P | G64: - | H64: 3 | I64: 0
A65: BMC22EE010 | B65: - | C65: - | D65: - | E65: - | F65: F | G65: - | H65: 1 | I65: 0
A66: BMC22EE011 | B66: - | C66: P | D66: - | E66: P | F66: F | G66: - | H66: 1 | I66: 0
A67: BMC22EE012 | B67: - | C67: - | D67: - | E67: P | F67: F | G67: F | H67: 2 | I67: 0
A72: DEPARTMENT PERFORMANCE ANALYSIS (BATCH 2022)
A73: Batch | B73: Total Students | C73: Total Pass | D73: Total Fail | E73: Pass % | F73: Fail %
A74: 2022 | B74: 10 | C74: 1 | D74: 9 | E74: 10 | F74: 90
A78: SUBJECT-WISE ANALYSIS (BATCH - 2022)
A79: SubCode | B79: Subject Name | C79: Pass% | D79: Fail% | E79: Pass | F79: Fail | G79: S | H79: A+ | I79: A | J79: B+ | K79: B | L79: C+ | M79: C | N79: D | O79: P | P79: F | Q79: FE | R79: Absent | S79: Withheld
A80: EEL334 | B80: EEL334 | C80: 100 | D80: 0 | E80: 1 | F80: 0 | G80: 0 | H80: 0 | I80: 0 | J80: 0 | K80: 0 | L80: 0 | M80: 0 | N80: 0 | O80: 1 | P80: 0 | Q80: 0 | R80: 0 | S80: 0
A81: EET302 | B81: LINEAR | C81: 33.333333 | D81: 66.666667 | E81: 2 | F81: 4 | G81: 0 | H81: 0 | I81: 0 | J81: 0 | K81: 0 | L81: 0 | M81: 0 | N81: 0 | O81: 2 | P81: 3 | Q81: 0 | R81: 1 | S81: 0
...

Sheet ME
A1: KTU RESULT ANALYZER
A2: BASELIOS MATHEWS II COLLEGE OF ENGINEERING
A3: B.Tech S6 (S, FE) Exam Dec 2025 (2019 Scheme) (S6 Result)
A4: Department: ME
A5: 📊 Overall Stats: 23 Students | 16 Regular | 7 Backlog
A7: SUBJECT ANALYTICS DASHBOARD
A8: Select Subject: | B8: Department
B10: Appeared | D10: Passed | G10: Failed | I10: Pass Rate | K10: Fail Rate
B11: =IFERROR(VLOOKUP("ME_" & UPPER($B$8), _DATA_!$A$2:$AZ$38, 2, FALSE), 0) -> 0 | D11: =IFERROR(VLOOKUP("ME_" & UPPER($B$8), _DATA_!$A$2:$AZ$38, 3, FALSE), 0) -> 0 | G11: =IFERROR(VLOOKUP("ME_" & UPPER($B$8), _DATA_!$A$2:$AZ$38, 4, FALSE), 0) -> 0 | I11: =IFERROR(VLOOKUP("ME_" & UPPER($B$8), _DATA_!$A$2:$AZ$38, 5, FALSE), 0) -> 0 | K11: =IFERROR(VLOOKUP("ME_" & UPPER($B$8), _DATA_!$A$2:$AZ$38, 6, FALSE), 0) -> 0
A32: BATCH - 2019
A33: Register No | B33: MET306 | C33: Arrears | D33: SGPA
A34: BMC19ME010 | B34: ABSENT | C34: 1 | D34: 0
A39: BATCH - 2021
A40: Register No | B40: HUT310 | C40: MET302 | D40: MET306 | E40: MET308 | F40: MET312 | G40: Arrears | H40: SGPA
A41: BMC21ME002 | B41: - | C41: C | D41: - | E41: - | F41: - | G41: 0 | H41: 6.5
A42: BMC21ME008 | B42: - | C42: - | D42: ABSENT | E42: - | F42: ABSENT | G42: 2 | H42: 0
A43: BMC21ME009 | B43: - | C43: F | D43: - | E43: - | F43: - | G43: 1 | H43: 0
A44: BMC21ME010 | B44: F | C44: F | D44: F | E44: - | F44: P | G44: 3 | H44: 0
A45: BMC21ME011 | B45: - | C45: F | D45: ABSENT | E45: - | F45: ABSENT | G45: 3 | H45: 0
A46: BMC21ME014 | B46: - | C46: - | D46: - | E46: F | F46: - | G46: 1 | H46: 0
A51: BATCH - 2022
A52: Register No | B52: HUT310 | C52: MET302 | D52: MET304 | E52: MET306 | F52: MET308 | G52: MET312 | H52: Arrears | I52: SGPA
A53: BMC22ME001 | B53: - | C53: F | D53: - | E53: ABSENT | F53: - | G53: F | H53: 3 | I53: 0
A54: BMC22ME002 | B54: - | C54: P | D54: F | E54: F | F54: F | G54: P | H54: 3 | I54: 0
A55: BMC22ME003 | B55: - | C55: F | D55: ABSENT | E55: - | F55: ABSENT | G55: ABSENT | H55: 4 | I55: 0
A56: BMC22ME005 | B56: ABSENT | C56: ABSENT | D56: ABSENT | E56: ABSENT | F56: F | G56: ABSENT | H56: 6 | I56: 0
A57: BMC22ME006 | B57: - | C57: F | D57: - | E57: ABSENT | F57: - | G57: F | H57: 3 | I57: 0
A58: BMC22ME007 | B58: F | C58: F | D58: ABSENT | E58: P | F58: F | G58: F | H58: 5 | I58: 0
A59: BMC22ME008 | B59: - | C59: - | D59: - | E59: - | F59: F | G59: - | H59: 1 | I59: 0
A60: BMC22ME009 | B60: F | C60: F | D60: ABSENT | E60: - | F60: F | G60: - | H60: 4 | I60: 0
A61: BMC22ME010 | B61: - | C61: F | D61: - | E61: ABSENT | F61: - | G61: - | H61: 2 | I61: 0
A62: BMC22ME012 | B62: - | C62: F | D62: F | E62: - | F62: F | G62: F | H62: 4 | I62: 0
A63: BMC22ME013 | B63: - | C63: F | D63: - | E63: - | F63: F | G63: F | H63: 3 | I63: 0
A64: BMC22ME014 | B64: ABSENT | C64: - | D64: - | E64: - | F64: - | G64: - | H64: 1 | I64: 0
... A68: BMC22ME019 | B68: F | C68: F | D68: ABSENT | E68: - | F68: - | G68: - | H68: 3 | I68: 0
A73: DEPARTMENT PERFORMANCE ANALYSIS (BATCH 2022)
A74: Batch | B74: Total Students | C74: Total Pass | D74: Total Fail | E74: Pass % | F74: Fail %
A75: 2022 | B75: 16 | C75: 0 | D75: 16 | E75: 0 | F75: 100
A79: SUBJECT-WISE ANALYSIS (BATCH - 2022)
A80: SubCode | B80: Subject Name | C80: Pass% | D80: Fail% | E80: Pass | F80: Fail | G80: S | H80: A+ | I80: A | J80: B+ | K80: B | L80: C+ | M80: C | N80: D | O80: P | P80: F | Q80: FE | R80: Absent | S80: Withheld
...

Sheet _STUDENTS_
A2: CE_CET302 | B2: Failed | C2: BMC20CE035 | D2: -
A3: CE_CET302 | B3: Failed | C3: BMC21CE003 | D3: -
A4: CE_CET302 | B4: Failed | C4: BMC21CE008 | D4: -
A5: CE_CET302 | B5: Failed | C5: BMC21CE012 | D5: -
A6: CE_CET304 | B6: Failed | C6: BMC20CE035 | D6: -
A7: CE_CET304 | B7: Failed | C7: BMC21CE003 | D7: -
A8: CE_CET306 | B8: Failed | C8: BMC22CE010 | D8: -
A9: CE_CET306 | B9: Failed | C9: BMC22CE013 | D9: -
A10: CE_CET308 | B10: Failed | C10: BMC22CE004 | D10: -
A11: CE_CET308 | B11: Failed | C11: BMC22CE005 | D11: -
A12: CE_CET352 | B12: Failed | C12: BMC21CE012 | D12: -
A13: CE_HUT300 | B13: Failed | C13: BMC20CE035 | D13: -
... A222: ME_MET312 | B222: Failed | C222: BMC22ME017 | D222: -

Sheet _DATA_
A1: Dept_Subject_Key | B1: Appeared | C1: Passed | D1: Failed | E1: Pass_P | F1: Fail_P | G1: S | H1: A+ | I1: A | J1: B+ | K1: B | L1: C+ | M1: C | N1: D | O1: P | P1: PASS | Q1: F | R1: FE | S1: Absent | T1: Withheld
A2: CE_DEPARTMENT | B2: 7 | C2: 1 | D2: 6 | E2: 14.285714 | F2: 85.714286 | G2: 0 | H2: 0 | I2: 0 | J2: 0 | K2: 0 | L2: 0 | M2: 1 | N2: 0 | O2: 4 | P2: 0 | Q2: 4 | R2: 0 | S2: 0 | T2: 0
A3: CE_CET302 | B3: 5 | C3: 1 | D3: 4 | E3: 20 | F3: 80 | G3: 0 | H3: 0 | I3: 0 | J3: 0 | K3: 0 | L3: 0 | M3: 0 | N3: 0 | O3: 1 | P3: 0 | Q3: 1 | R3: 0 | S3: 0 | T3: 0
A4: CE_CET304 | B4: 2 | C4: 0 | D4: 2 | E4: 0 | F4: 100 | G4: 0 | H4: 0 | I4: 0 | J4: 0 | K4: 0 | L4: 0 | M4: 0 | N4: 0 | O4: 0 | P4: 0 | Q4: 2 | R4: 0 | S4: 0 | T4: 0
A5: CE_CET306 | B5: 4 | C5: 2 | D5: 2 | E5: 50 | F5: 50 | G5: 0 | H5: 0 | I5: 0 | J5: 0 | K5: 0 | L5: 0 | M5: 1 | N5: 0 | O5: 1 | P5: 0 | Q5: 0 | R5: 0 | S5: 0 | T5: 0
A6: CE_CET308 | B6: 4 | C6: 2 | D6: 2 | E6: 50 | F6: 50 | G6: 0 | H6: 0 | I6: 0 | J6: 0 | K6: 0 | L6: 0 | M6: 0 | N6: 0 | O6: 2 | P6: 0 | Q6: 2 | R6: 0 | S6: 0 | T6: 0
A7: CE_CET352 | B7: 2 | C7: 1 | D7: 1 | E7: 50 | F7: 50 | G7: 0 | H7: 0 | I7: 0 | J7: 0 | K7: 0 | L7: 0 | M7: 0 | N7: 0 | O7: 1 | P7: 0 | Q7: 0 | R7: 0 | S7: 0 | T7: 0
A8: CE_HUT300 | B8: 7 | C8: 2 | D8: 5 | E8: 28.571429 | F8: 71.428571 | G8: 0 | H8: 0 | I8: 0 | J8: 0 | K8: 0 | L8: 0 | M8: 1 | N8: 0 | O8: 1 | P8: 0 | Q8: 4 | R8: 0 | S8: 0 | T8: 0
A9: CS_DEPARTMENT | B9: 48 | C9: 11 | D9: 37 | E9: 22.916667 | F9: 77.083333 | G9: 0 | H9: 0 | I9: 0 | J9: 0 | K9: 2 | L9: 3 | M9: 4 | N9: 10 | O9: 15 | P9: 0 | Q9: 63 | R9: 0 | S9: 0 | T9: 0
A10: CS_CST302 | B10: 20 | C10: 4 | D10: 16 | E10: 20 | F10: 80 | G10: 0 | H10: 0 | I10: 0 | J10: 0 | K10: 0 | L10: 0 | M10: 2 | N10: 0 | O10: 2 | P10: 0 | Q10: 12 | R10: 0 | S10: 0 | T10: 0
A11: CS_CST304 | B11: 12 | C11: 7 | D11: 5 | E11: 58.333333 | F11: 41.666667 | G11: 0 | H11: 0 | I11: 0 | J11: 0 | K11: 1 | L11: 1 | M11: 0 | N11: 3 | O11: 2 | P11: 0 | Q11: 2 | R11: 0 | S11: 0 | T11: 0
A12: CS_CST306 | B12: 9 | C12: 1 | D12: 8 | E12: 11.111111 | F12: 88.888889 | G12: 0 | H12: 0 | I12: 0 | J12: 0 | K12: 0 | L12: 0 | M12: 0 | N12: 0 | O12: 1 | P12: 0 | Q12: 3 | R12: 0 | S12: 0 | T12: 0
A13: CS_CST308 | B13: 26 | C13: 10 | D13: 16 | E13: 38.461538 | F13: 61.538462 | G13: 0 | H13: 0 | I13: 0 | J13: 0 | K13: 1 | L13: 2 | M13: 0 | N13: 2 | O13: 5 | P13: 0 | Q13: 14 | R13: 0 | S13: 0 | T13: 0
... A38: ME_MET312 | B38: 13 | C38: 2 | D38: 11 | E38: 15.384615 | F38: 84.615385 | G38: 0 | H38: 0 | I38: 0 | J38: 0 | K38: 0 | L38: 0 | M38: 0 | N38: 0 | O38: 2 | P38: 0 | Q38: 5 | R38: 0 | S38: 0 | T38: 0
