Workbook

Sheet All Results
A1: Register No | B1: Year | C1: Dept | D1: Scheme | E1: Subject | F1: Subject Name | G1: Grade | H1: SGPA
A2: BMC19CS014 | B2: 2019 | C2: CS | D2: 2019 | E2: CST301 | F2: FORMAL | G2: F | H2: 0
A3: BMC19CS020 | B3: 2019 | C3: CS | D3: 2019 | E3: CST301 | F3: FORMAL | G3: F | H3: 0
A4: BMC19CS024 | B4: 2019 | C4: CS | D4: 2019 | E4: CST301 | F4: FORMAL | G4: ABSENT | H4: 0
A5: BMC19CS024 | B5: 2019 | C5: CS | D5: 2019 | E5: CST303 | F5: COMPUTER | G5: ABSENT | H5: 0
A6: BMC19CS024 | B6: 2019 | C6: CS | D6: 2019 | E6: CST305 | F6: SYSTEM | G6: ABSENT | H6: 0
A7: BMC19CS024 | B7: 2019 | C7: CS | D7: 2019 | E7: CST307 | F7: CST307 | G7: ABSENT | H7: 0
A8: BMC19CS046 | B8: 2019 | C8: CS | D8: 2019 | E8: CST301 | F8: FORMAL | G8: F | H8: 0
A9: BMC20CS019 | B9: 2020 | C9: CS | D9: 2019 | E9: CST301 | F9: FORMAL | G9: F | H9: 0
A10: BMC20CS019 | B10: 2020 | C10: CS | D10: 2019 | E10: CST309 | F10: MANAGEMENT OF | G10: F | H10: 0
A11: BMC20CS029 | B11: 2020 | C11: CS | D11: 2019 | E11: MCN301 | F11: DISASTER | G11: F | H11: 0
A12: BMC20CS029 | B12: 2020 | C12: CS | D12: 2019 | E12: CST301 | F12: FORMAL | G12: F | H12: 0
A13: BMC20CS029 | B13: 2020 | C13: CS | D13: 2019 | E13: CST307 | F13: CST307 | G13: F | H13: 0
... A1863: BMC23AI043 | B1863: 2023 | C1863: AI | D1863: 2019 | E1863: AIT301 | F1863: AIT301 | G1863: D | H1863: 7.29

Sheet OVERALL SUMMARY
A1: KTU RESULT ANALYZER - OVERALL SUMMARY REPORT
A2: BASELIOS MATHEWS II COLLEGE OF ENGINEERING
A3: B.Tech S5 (R, S) Exam Nov 2025 (2019 Scheme) (S5 Result)
A5: OVERALL STATISTICS - REGULAR STUDENTS ONLY
A6: Total Reg Students | B6: Total Passed | C6: Total Failed | D6: Overall Pass % | E6: Overall Fail %
A7: 197 | B7: 70 | C7: 127 | D7: 35.532995 | E7: 64.467005
A11: DEPARTMENT-WISE PERFORMANCE ANALYSIS
A12: Department Name | B12: Total Regular Students | C12: Total Pass | D12: Total Fail | E12: Pass % | F12: Fail %
A13: AE | B13: 2 | C13: 0 | D13: 2 | E13: 0 | F13: 100
A14: AI | B14: 42 | C14: 16 | D14: 26 | E14: 38.095238 | F14: 61.904762
A15: CE | B15: 18 | C15: 7 | D15: 11 | E15: 38.888889 | F15: 61.111111
A16: CS | B16: 95 | C16: 34 | D16: 61 | E16: 35.789474 | F16: 64.210526
A17: EC | B17: 13 | C17: 4 | D17: 9 | E17: 30.769231 | F17: 69.230769
A18: EE | B18: 13 | C18: 6 | D18: 7 | E18: 46.153846 | F18: 53.846154
A19: ME | B19: 14 | C19: 3 | D19: 11 | E19: 21.428571 | F19: 78.571429
A22: TOP 5 PERFORMING SUBJECTS
A23: Rank | B23: Subject Code | C23: Department | D23: Pass % | E23: Fail % | F23: Total Students | G23: Pass | H23: Fail
A24: 1 | B24: CSL333 | C24: CS | D24: 100 | E24: 0 | F24: 95 | G24: 95 | H24: 0
A25: 2 | B25: MEL331 | C25: ME | D25: 100 | E25: 0 | F25: 14 | G25: 14 | H25: 0
A26: 3 | B26: MEL333 | C26: ME | D26: 100 | E26: 0 | F26: 14 | G26: 14 | H26: 0
A27: 4 | B27: CSL331 | C27: CS | D27: 98.947368 | E27: 1.0526316 | F27: 95 | G27: 94 | H27: 1
A28: 5 | B28: AIL333 | C28: AI | D28: 97.619048 | E28: 2.3809524 | F28: 42 | G28: 41 | H28: 1
A31: BOTTOM 5 PERFORMING SUBJECTS (NEEDS ATTENTION)
A32: Rank | B32: Subject Code | C32: Department | D32: Pass % | E32: Fail % | F32: Total Students | G32: Pass | H32: Fail
A33: 1 | B33: MET303 | C33: ME | D33: 28.571429 | E33: 71.428571 | F33: 14 | G33: 4 | H33: 10
A34: 2 | B34: MET307 | C34: ME | D34: 28.571429 | E34: 71.428571 | F34: 14 | G34: 4 | H34: 10
A35: 3 | B35: ECT301 | C35: EC | D35: 30.769231 | E35: 69.230769 | F35: 13 | G35: 4 | H35: 9
A36: 4 | B36: ECT307 | C36: EC | D36: 30.769231 | E36: 69.230769 | F36: 13 | G36: 4 | H36: 9
A37: 5 | B37: CST307 | C37: CS | D37: 36.842105 | E37: 63.157895 | F37: 95 | G37: 35 | H37: 60

Sheet AE
A1: KTU RESULT ANALYZER
A2: BASELIOS MATHEWS II COLLEGE OF ENGINEERING
A3: B.Tech S5 (R, S) Exam Nov 2025 (2019 Scheme) (S5 Result)
A4: Department: AE
A5: 📊 Overall Stats: 2 Students | 2 Regular | 0 Backlog
A7: SUBJECT ANALYTICS DASHBOARD
A8: Select Subject: | B8: Department
A12: Appeared | E12: Passed | I12: Failed | L12: Pass Rate | O12: Fail Rate
A13: =IFERROR(VLOOKUP("AE_" & UPPER($B$8), _DATA_!$A$2:$AZ$62, 2, FALSE), 0) -> 0 | E13: =IFERROR(VLOOKUP("AE_" & UPPER($B$8), _DATA_!$A$2:$AZ$62, 3, FALSE), 0) -> 0 | I13: =IFERROR(VLOOKUP("AE_" & UPPER($B$8), _DATA_!$A$2:$AZ$62, 4, FALSE), 0) -> 0 | L13: =IFERROR(VLOOKUP("AE_" & UPPER($B$8), _DATA_!$A$2:$AZ$62, 5, FALSE), 0) -> 0 | O13: =IFERROR(VLOOKUP("AE_" & UPPER($B$8), _DATA_!$A$2:$AZ$62, 6, FALSE), 0) -> 0
A34: BATCH - 2019
A35: Register No | B35: AET301 | C35: AET307 | D35: Arrears | E35: SGPA
A36: BMC19AE001 | B36: - | C36: ABSENT | D36: 1 | E36: 0
A37: BMC19AE004 | B37: F | C37: - | D37: 1 | E37: 0
A42: DEPARTMENT PERFORMANCE ANALYSIS (BATCH 2019)
A43: Batch | B43: Total Students | C43: Total Pass | D43: Total Fail | E43: Pass % | F43: Fail %
A44: 2019 | B44: 2 | C44: 0 | D44: 2 | E44: 0 | F44: 100
A48: SUBJECT-WISE ANALYSIS (BATCH - 2019)
A49: SubCode | B49: Subject Name | C49: Pass% | D49: Fail% | E49: Pass | F49: Fail | G49: S | H49: A+ | I49: A | J49: B+ | K49: B | L49: C+ | M49: C | N49: D | O49: P | P49: F | Q49: FE | R49: Absent | S49: Withheld
A50: AET301 | B50: CONTROL | C50: 0 | D50: 100 | E50: 0 | F50: 1 | G50: 0 | H50: 0 | I50: 0 | J50: 0 | K50: 0 | L50: 0 | M50: 0 | N50: 0 | O50: 0 | P50: 1 | Q50: 0 | R50: 0 | S50: 0
A51: AET307 | B51: ANALOG | C51: 0 | D51: 100 | E51: 0 | F51: 1 | G51: 0 | H51: 0 | I51: 0 | J51: 0 | K51: 0 | L51: 0 | M51: 0 | N51: 0 | O51: 0 | P51: 0 | Q51: 0 | R51: 1 | S51: 0
AZ501: ="AE_" & UPPER($B$8) -> 0
AZ506: ="S - " & TEXT($BA$506/MAX($BA$521, 1), "0%") -> 0 | BA506: =IFERROR(VLOOKUP($AZ$501, _DATA_!$A$2:$AZ$62, 7, FALSE), 0) -> 0
AZ507: ="A+ - " & TEXT($BA$507/MAX($BA$521, 1), "0%") -> 0 | BA507: =IFERROR(VLOOKUP($AZ$501, _DATA_!$A$2:$AZ$62, 8, FALSE), 0) -> 0
AZ508: ="A - " & TEXT($BA$508/MAX($BA$521, 1), "0%") -> 0 | BA508: =IFERROR(VLOOKUP($AZ$501, _DATA_!$A$2:$AZ$62, 9, FALSE), 0) -> 0
AZ509: ="B+ - " & TEXT($BA$509/MAX($BA$521, 1), "0%") -> 0 | BA509: =IFERROR(VLOOKUP($AZ$501, _DATA_!$A$2:$AZ$62, 10, FALSE), 0) -> 0
AZ510: ="B - " & TEXT($BA$510/MAX($BA$521, 1), "0%") -> 0 | BA510: =IFERROR(VLOOKUP($AZ$501, _DATA_!$A$2:$AZ$62, 11, FALSE), 0) -> 0
AZ511: ="C+ - " & TEXT($BA$511/MAX($BA$521, 1), "0%") -> 0 | BA511: =IFERROR(VLOOKUP($AZ$501, _DATA_!$A$2:$AZ$62, 12, FALSE), 0) -> 0
AZ512: ="C - " & TEXT($BA$512/MAX($BA$521, 1), "0%") -> 0 | BA512: =IFERROR(VLOOKUP($AZ$501, _DATA_!$A$2:$AZ$62, 13, FALSE), 0) -> 0
AZ513: ="D - " & TEXT($BA$513/MAX($BA$521, 1), "0%") -> 0 | BA513: =IFERROR(VLOOKUP($AZ$501, _DATA_!$A$2:$AZ$62, 14, FALSE), 0) -> 0
AZ514: ="P - " & TEXT($BA$514/MAX($BA$521, 1), "0%") -> 0 | BA514: =IFERROR(VLOOKUP($AZ$501, _DATA_!$A$2:$AZ$62, 15, FALSE), 0) -> 0
AZ515: ="PASS - " & TEXT($BA$515/MAX($BA$521, 1), "0%") -> 0 | BA515: =IFERROR(VLOOKUP($AZ$501, _DATA_!$A$2:$AZ$62, 16, FALSE), 0) -> 0
AZ516: ="F - " & TEXT($BA$516/MAX($BA$521, 1), "0%") -> 0 | BA516: =IFERROR(VLOOKUP($AZ$501, _DATA_!$A$2:$AZ$62, 17, FALSE), 0) -> 0
AZ517: ="FE - " & TEXT($BA$517/MAX($BA$521, 1), "0%") -> 0 | BA517: =IFERROR(VLOOKUP($AZ$501, _DATA_!$A$2:$AZ$62, 18, FALSE), 0) -> 0
AZ518: ="Absent - " & TEXT($BA$518/MAX($BA$521, 1), "0%") -> 0 | BA518: =IFERROR(VLOOKUP($AZ$501, _DATA_!$A$2:$AZ$62, 19, FALSE), 0) -> 0
AZ519: ="Withheld - " & TEXT($BA$519/MAX($BA$521, 1), "0%") -> 0 | BA519: =IFERROR(VLOOKUP($AZ$501, _DATA_!$A$2:$AZ$62, 20, FALSE), 0) -> 0
AZ521: Appeared | BA521: =IFERROR(VLOOKUP($AZ$501, _DATA_!$A$2:$T$62, 2, FALSE), 0) -> 0
AZ522: Passed | BA522: =IFERROR(VLOOKUP($AZ$501, _DATA_!$A$2:$T$62, 3, FALSE), 0) -> 0
AZ523: Failed | BA523: =IFERROR(VLOOKUP($AZ$501, _DATA_!$A$2:$T$62, 4, FALSE), 0) -> 0

Sheet AI
A1: KTU RESULT ANALYZER
A2: BASELIOS MATHEWS II COLLEGE OF ENGINEERING
A3: B.Tech S5 (R, S) Exam Nov 2025 (2019 Scheme) (S5 Result)
A4: Department: AI
A5: 📊 Overall Stats: 42 Students | 42 Regular | 0 Backlog
A7: SUBJECT ANALYTICS DASHBOARD
A8: Select Subject: | B8: Department
A12: Appeared | E12: Passed | I12: Failed | L12: Pass Rate | O12: Fail Rate
A13: =IFERROR(VLOOKUP("AI_" & UPPER($B$8), _DATA_!$A$2:$AZ$62, 2, FALSE), 0) -> 0 | E13: =IFERROR(VLOOKUP("AI_" & UPPER($B$8), _DATA_!$A$2:$AZ$62, 3, FALSE), 0) -> 0 | I13: =IFERROR(VLOOKUP("AI_" & UPPER($B$8), _DATA_!$A$2:$AZ$62, 4, FALSE), 0) -> 0 | L13: =IFERROR(VLOOKUP("AI_" & UPPER($B$8), _DATA_!$A$2:$AZ$62, 5, FALSE), 0) -> 0 | O13: =IFERROR(VLOOKUP("AI_" & UPPER($B$8), _DATA_!$A$2:$AZ$62, 6, FALSE), 0) -> 0
A34: BATCH - 2023
A35: Register No | B35: AIL333 | C35: AIT301 | D35: AIT307 | E35: AML331 | F35: AMT305 | G35: CST303 | H35: CST309 | I35: MCN301 | J35: Arrears | K35: SGPA
A36: BMC23AI001 | B36: A | C36: A+ | D36: A | E36: S | F36: A | G36: B | H36: C+ | I36: A+ | J36: 0 | K36: 8.43
A37: BMC23AI002 | B37: D | C37: C | D37: F | E37: S | F37: P | G37: F | H37: F | I37: D | J37: 3 | K37: 4
A38: BMC23AI003 | B38: S | C38: B+ | D38: A | E38: S | F38: B+ | G38: P | H38: B+ | I38: B+ | J38: 0 | K38: 8.29
A39: BMC23AI005 | B39: S | C39: A | D39: S | E39: S | F39: A | G39: A | H39: A | I39: A | J39: 0 | K39: 9.14
A40: BMC23AI006 | B40: D | C40: P | D40: F | E40: S | F40: ABSENT | G40: F | H40: ABSENT | I40: ABSENT | J40: 5 | K40: 3.07
A41: BMC23AI007 | B41: B+ | C41: C | D41: P | E41: S | F41: P | G41: F | H41: F | I41: D | J41: 2 | K41: 5.07
A42: BMC23AI008 | B42: C+ | C42: C | D42: P | E42: A | F42: F | G42: F | H42: F | I42: P | J42: 3 | K42: 3.93
A43: BMC23AI009 | B43: B+ | C43: B | D43: B | E43: S | F43: C+ | G43: P | H43: C+ | I43: B | J43: 0 | K43: 7.5
A44: BMC23AI010 | B44: S | C44: B | D44: C+ | E44: S | F44: D | G44: P | H44: F | I44: C+ | J44: 1 | K44: 6.57
A45: BMC23AI011 | B45: B | C45: C | D45: P | E45: A+ | F45: F | G45: F | H45: F | I45: D | J45: 3 | K45: 4.07
A46: BMC23AI012 | B46: A+ | C46: C | D46: A | E46: A+ | F46: A | G46: D | H46: C+ | I46: A+ | J46: 0 | K46: 7.79
A47: BMC23AI013 | B47: D | C47: P | D47: P | E47: S | F47: F | G47: F | H47: F | I47: P | J47: 3 | K47: 3.86
... A77: BMC23AI043 | B77: A+ | C77: D | D77: C+ | E77: S | F77: D | G77: P | H77: B | I77: B+ | J77: 0 | K77: 7.29
A82: DEPARTMENT PERFORMANCE ANALYSIS (BATCH 2023)
A83: Batch | B83: Total Students | C83: Total Pass | D83: Total Fail | E83: Pass % | F83: Fail %
A84: 2023 | B84: 42 | C84: 16 | D84: 26 | E84: 38.095238 | F84: 61.904762
A88: SUBJECT-WISE ANALYSIS (BATCH - 2023)
A89: SubCode | B89: Subject Name | C89: Pass% | D89: Fail% | E89: Pass | F89: Fail | G89: S | H89: A+ | I89: A | J89: B+ | K89: B | L89: C+ | M89: C | N89: D | O89: P | P89: F | Q89: FE | R89: Absent | S89: Withheld
A90: AIL333 | B90: AIL333 | C90: 97.619048 | D90: 2.3809524 | E90: 41 | F90: 1 | G90: 10 | H90: 8 | I90: 5 | J90: 7 | K90: 3 | L90: 1 | M90: 1 | N90: 6 | O90: 0 | P90: 0 | Q90: 0 | R90: 0 | S90: 1
A91: AIT301 | B91: AIT301 | C91: 90.47619 | D91: 9.5238095 | E91: 38 | F91: 4 | G91: 0 | H91: 1 | I91: 2 | J91: 3 | K91: 8 | L91: 2 | M91: 8 | N91: 6 | O91: 8 | P91: 3 | Q91: 0 | R91: 0 | S91: 1
A92: AIT307 | B92: AIT307 | C92: 78.571429 | D92: 21.428571 | E92: 33 | F92: 9 | G92: 2 | H92: 1 | I92: 4 | J92: 2 | K92: 1 | L92: 4 | M92: 6 | N92: 3 | O92: 10 | P92: 8 | Q92: 0 | R92: 0 | S92: 1
A93: AML331 | B93: AML331 | C93: 97.619048 | D93: 2.3809524 | E93: 41 | F93: 1 | G93: 30 | H93: 10 | I93: 1 | J93: 0 | K93: 0 | L93: 0 | M93: 0 | N93: 0 | O93: 0 | P93: 0 | Q93: 0 | R93: 0 | S93: 1
A94: AMT305 | B94: AMT305 | C94: 54.761905 | D94: 45.238095 | E94: 23 | F94: 19 | G94: 0 | H94: 1 | I94: 5 | J94: 2 | K94: 0 | L94: 2 | M94: 3 | N94: 3 | O94: 7 | P94: 17 | Q94: 0 | R94: 1 | S94: 1
A95: CST303 | B95: COMPUTER | C95: 40.47619 | D95: 59.52381 | E95: 17 | F95: 25 | G95: 0 | H95: 0 | I95: 1 | J95: 1 | K95: 3 | L95: 0 | M95: 0 | N95: 2 | O95: 10 | P95: 24 | Q95: 0 | R95: 0 | S95: 1
A96: CST309 | B96: MANAGEMENT OF | C96: 50 | D96: 50 | E96: 21 | F96: 21 | G96: 0 | H96: 1 | I96: 2 | J96: 2 | K96: 3 | L96: 3 | M96: 0 | N96: 5 | O96: 5 | P96: 19 | Q96: 0 | R96: 1 | S96: 1
A97: MCN301 | B97: DISASTER | C97: 95.238095 | D97: 4.7619048 | E97: 40 | F97: 2 | G97: 0 | H97: 4 | I97: 4 | J97: 4 | K97: 4 | L97: 8 | M97: 4 | N97: 8 | O97: 4 | P97: 0 | Q97: 0 | R97: 1 | S97: 1
AZ501: ="AI_" & UPPER($B$8) -> 0
AZ506: ="S - " & TEXT($BA$506/MAX($BA$521, 1), "0%") -> 0 | BA506: =IFERROR(VLOOKUP($AZ$501, _DATA_!$A$2:$AZ$62, 7, FALSE), 0) -> 0
AZ507: ="A+ - " & TEXT($BA$507/MAX($BA$521, 1), "0%") -> 0 | BA507: =IFERROR(VLOOKUP($AZ$501, _DATA_!$A$2:$AZ$62, 8, FALSE), 0) -> 0
...

Sheet CE
A1: KTU RESULT ANALYZER
A2: BASELIOS MATHEWS II COLLEGE OF ENGINEERING
A3: B.Tech S5 (R, S) Exam Nov 2025 (2019 Scheme) (S5 Result)
A4: Department: CE
A5: 📊 Overall Stats: 34 Students | 18 Regular | 16 Backlog
A7: SUBJECT ANALYTICS DASHBOARD
A8: Select Subject: | B8: Department
A12: Appeared | E12: Passed | I12: Failed | L12: Pass Rate | O12: Fail Rate
A13: =IFERROR(VLOOKUP("CE_" & UPPER($B$8), _DATA_!$A$2:$AZ$62, 2, FALSE), 0) -> 0 | E13: =IFERROR(VLOOKUP("CE_" & UPPER($B$8), _DATA_!$A$2:$AZ$62, 3, FALSE), 0) -> 0 | I13: =IFERROR(VLOOKUP("CE_" & UPPER($B$8), _DATA_!$A$2:$AZ$62, 4, FALSE), 0) -> 0 | L13: =IFERROR(VLOOKUP("CE_" & UPPER($B$8), _DATA_!$A$2:$AZ$62, 5, FALSE), 0) -> 0 | O13: =IFERROR(VLOOKUP("CE_" & UPPER($B$8), _DATA_!$A$2:$AZ$62, 6, FALSE), 0) -> 0
A34: BATCH - 2019
A35: Register No | B35: CET301 | C35: CET303 | D35: Arrears | E35: SGPA
A36: BMC19CE025 | B36: ABSENT | C36: - | D36: 1 | E36: 0
A37: BMC19CE026 | B37: F | C37: F | D37: 2 | E37: 0
A42: BATCH - 2020
A43: Register No | B43: CET301 | C43: CET303 | D43: CET307 | E43: Arrears | F43: SGPA
A44: BMC20CE007 | B44: ABSENT | C44: ABSENT | D44: - | E44: 2 | F44: 0
A45: BMC20CE017 | B45: C | C45: F | D45: - | E45: 1 | F45: 3.25
A46: BMC20CE048 | B46: ABSENT | C46: ABSENT | D46: ABSENT | E46: 3 | F46: 0
A51: BATCH - 2021
A52: Register No | B52: CET301 | C52: CET303 | D52: CET305 | E52: CET307 | F52: CET309 | G52: MCN301 | H52: Arrears | I52: SGPA
A53: BMC21CE003 | B53: F | C53: F | D53: - | E53: F | F53: - | G53: - | H53: 3 | I53: 0
A54: BMC21CE008 | B54: P | C54: ABSENT | D54: F | E54: F | F54: - | G54: - | H54: 3 | I54: 1.38
A55: BMC21CE012 | B55: F | C55: F | D55: - | E55: F | F55: C | G55: C | H55: 3 | I55: 1.3
A56: BMC21CE020 | B56: - | C56: - | D56: - | E56: - | F56: ABSENT | G56: - | H56: 1 | I56: 0
A57: BMC21CE023 | B57: ABSENT | C57: F | D57: - | E57: ABSENT | F57: - | G57: - | H57: 3 | I57: 0
A58: BMC21CE024 | B58: - | C58: F | D58: F | E58: ABSENT | F58: - | G58: - | H58: 3 | I58: 0
A63: BATCH - 2022
A64: Register No | B64: CET303 | C64: CET309 | D64: HUT300 | E64: MCN301 | F64: Arrears | G64: SGPA
A65: BMC22CE004 | B65: - | C65: D | D65: ABSENT | E65: - | F65: 1 | G65: 2.57
A66: BMC22CE005 | B66: F | C66: - | D66: - | E66: - | F66: 1 | G66: 0
A67: BMC22CE008 | B67: ABSENT | C67: P | D67: - | E67: - | F67: 1 | G67: 2.36
A68: BMC22CE011 | B68: - | C68: - | D68: F | E68: - | F68: 1 | G68: 0
A69: BMC22CE013 | B69: - | C69: C | D69: ABSENT | E69: C | F69: 1 | G69: 2.79
A74: BATCH - 2023
A75: Register No | B75: CEL331 | C75: CEL333 | D75: CET301 | E75: CET303 | F75: CET305 | G75: CET307 | H75: CET309 | I75: MCN301 | J75: Arrears | K75: SGPA
A76: BMC23CE001 | B76: B | C76: B+ | D76: F | E76: F | F76: P | G76: F | H76: C | I76: F | J76: 4 | K76: 3.15
A77: BMC23CE002 | B77: A | C77: B+ | D77: B | E77: F | F77: C | G77: F | H77: C+ | I77: C+ | J77: 2 | K77: 4.78
A78: BMC23CE003 | B78: C | C78: C | D78: F | E78: F | F78: F | G78: F | H78: F | I78: F | J78: 6 | K78: 1.13
A79: BMC23CE004 | B79: A+ | C79: A+ | D79: A | E79: C+ | F79: C+ | G79: C+ | H79: C+ | I79: B+ | J79: 0 | K79: 7.61
A80: BMC23CE005 | B80: S | C80: S | D80: S | E80: A | F80: A+ | G80: A | H80: A | I80: S | J80: 0 | K80: 9.11
...

Sheet CS
A1: KTU RESULT ANALYZER
A2: BASELIOS MATHEWS II COLLEGE OF ENGINEERING
A3: B.Tech S5 (R, S) Exam Nov 2025 (2019 Scheme) (S5 Result)
A4: Department: CS
A5: 📊 Overall Stats: 152 Students | 95 Regular | 57 Backlog
A7: SUBJECT ANALYTICS DASHBOARD
A8: Select Subject: | B8: Department
A12: Appeared | E12: Passed | I12: Failed | L12: Pass Rate | O12: Fail Rate
A13: =IFERROR(VLOOKUP("CS_" & UPPER($B$8), _DATA_!$A$2:$AZ$62, 2, FALSE), 0) -> 0 | E13: =IFERROR(VLOOKUP("CS_" & UPPER($B$8), _DATA_!$A$2:$AZ$62, 3, FALSE), 0) -> 0 | I13: =IFERROR(VLOOKUP("CS_" & UPPER($B$8), _DATA_!$A$2:$AZ$62, 4, FALSE), 0) -> 0 | L13: =IFERROR(VLOOKUP("CS_" & UPPER($B$8), _DATA_!$A$2:$AZ$62, 5, FALSE), 0) -> 0 | O13: =IFERROR(VLOOKUP("CS_" & UPPER($B$8), _DATA_!$A$2:$AZ$62, 6, FALSE), 0) -> 0
A34: BATCH - 2019
A35: Register No | B35: CST301 | C35: CST303 | D35: CST305 | E35: CST307 | F35: Arrears | G35: SGPA
A36: BMC19CS014 | B36: F | C36: - | D36: - | E36: - | F36: 1 | G36: 0
A37: BMC19CS020 | B37: F | C37: - | D37: - | E37: - | F37: 1 | G37: 0
A38: BMC19CS024 | B38: ABSENT | C38: ABSENT | D38: ABSENT | E38: ABSENT | F38: 4 | G38: 0
A39: BMC19CS046 | B39: F | C39: - | D39: - | E39: - | F39: 1 | G39: 0
A44: BATCH - 2020
A45: Register No | B45: CST301 | C45: CST307 | D45: CST309 | E45: MCN301 | F45: Arrears | G45: SGPA
A46: BMC20CS019 | B46: F | C46: - | D46: F | E46: - | F46: 2 | G46: 0
A47: BMC20CS029 | B47: F | C47: F | D47: F | E47: F | F47: 4 | G47: 0
A48: BMC20CS033 | B48: ABSENT | C48: - | D48: ABSENT | E48: - | F48: 2 | G48: 0
A49: BMC20CS050 | B49: F | C49: - | D49: - | E49: - | F49: 1 | G49: 0
A50: BMC20CS053 | B50: F | C50: - | D50: - | E50: - | F50: 1 | G50: 0
A51: BMC20CS055 | B51: F | C51: - | D51: - | E51: - | F51: 1 | G51: 0
A52: BMC20CS056 | B52: - | C52: - | D52: ABSENT | E52: - | F52: 1 | G52: 0
A53: BMC20CS057 | B53: F | C53: - | D53: - | E53: - | F53: 1 | G53: 0
A58: BATCH - 2021
A59: Register No | B59: CST301 | C59: CST307 | D59: CST309 | E59: MCN301 | F59: Arrears | G59: SGPA
A60: BMC21CS013 | B60: F | C60: - | D60: - | E60: - | F60: 1 | G60: 0
A61: BMC21CS024 | B61: D | C61: F | D61: F | E61: - | F61: 2 | G61: 2.18
A62: BMC21CS025 | B62: F | C62: - | D62: - | E62: - | F62: 1 | G62: 0
A63: BMC21CS034 | B63: F | C63: - | D63: - | E63: - | F63: 1 | G63: 0
A64: BMC21CS037 | B64: - | C64: - | D64: - | E64: F | F64: 1 | G64: 0
A65: BMC21CS039 | B65: F | C65: ABSENT | D65: - | E65: - | F65: 2 | G65: 0
A70: BATCH - 2022
A71: Register No | B71: CST301 | C71: CST303 | D71: CST305 | E71: CST307 | F71: CST309 | G71: HUT300 | H71: MCN301 | I71: Arrears | J71: SGPA
A72: BMC22CS001 | B72: - | C72: - | D72: - | E72: - | F72: - | G72: - | H72: P | I72: 0 | J72: 0
A73: BMC22CS005 | B73: - | C73: F | D73: - | E73: F | F73: - | G73: - | H73: F | I73: 3 | J73: 0
A74: BMC22CS009 | B74: F | C74: F | D74: - | E74: F | F74: - | G74: - | H74: D | I74: 3 | J74: 0
A75: BMC22CS011 | B75: - | C75: - | D75: F | E75: F | F75: - | G75: F | H75: - | I75: 3 | J75: 0
A76: BMC22CS014 | B76: F | C76: - | D76: - | E76: - | F76: - | G76: - | H76: C+ | I76: 1 | J76: 0
...

Sheet EC
A1: KTU RESULT ANALYZER
A2: BASELIOS MATHEWS II COLLEGE OF ENGINEERING
A3: B.Tech S5 (R, S) Exam Nov 2025 (2019 Scheme) (S5 Result)
A4: Department: EC
A5: 📊 Overall Stats: 25 Students | 13 Regular | 12 Backlog
A7: SUBJECT ANALYTICS DASHBOARD
A8: Select Subject: | B8: Department
A12: Appeared | E12: Passed | I12: Failed | L12: Pass Rate | O12: Fail Rate
A13: =IFERROR(VLOOKUP("EC_" & UPPER($B$8), _DATA_!$A$2:$AZ$62, 2, FALSE), 0) -> 0 | E13: =IFERROR(VLOOKUP("EC_" & UPPER($B$8), _DATA_!$A$2:$AZ$62, 3, FALSE), 0) -> 0 | I13: =IFERROR(VLOOKUP("EC_" & UPPER($B$8), _DATA_!$A$2:$AZ$62, 4, FALSE), 0) -> 0 | L13: =IFERROR(VLOOKUP("EC_" & UPPER($B$8), _DATA_!$A$2:$AZ$62, 5, FALSE), 0) -> 0 | O13: =IFERROR(VLOOKUP("EC_" & UPPER($B$8), _DATA_!$A$2:$AZ$62, 6, FALSE), 0) -> 0
A34: BATCH - 2020
A35: Register No | B35: ECT303 | C35: ECT307 | D35: Arrears | E35: SGPA
A36: BMC20EC010 | B36: F | C36: F | D36: 2 | E36: 0
A41: BATCH - 2021
A42: Register No | B42: ECT305 | C42: ECT307 | D42: Arrears | E42: SGPA
A43: BMC21EC002 | B43: - | C43: P | D43: 0 | E43: 5.5
A44: BMC21EC003 | B44: D | C44: - | D44: 0 | E44: 6
A45: BMC21EC008 | B45: P | C45: - | D45: 0 | E45: 5.5
A46: BMC21EC010 | B46: - | C46: P | D46: 0 | E46: 5.5
A51: BATCH - 2022
A52: Register No | B52: ECL333 | C52: ECT301 | D52: ECT303 | E52: ECT305 | F52: ECT307 | G52: HUT300 | H52: MCN301 | I52: Arrears | J52: SGPA
A53: BMC22EC001 | B53: - | C53: F | D53: F | E53: F | F53: ABSENT | G53: - | H53: P | I53: 4 | J53: 0
A54: BMC22EC013 | B54: C | C54: F | D54: F | E54: F | F54: F | G54: F | H54: F | I54: 6 | J54: 0.62
A55: BMC22EC015 | B55: - | C55: F | D55: F | E55: - | F55: F | G55: F | H55: F | I55: 5 | J55: 0
A56: BMC22EC017 | B56: - | C56: - | D56: - | E56: - | F56: P | G56: - | H56: - | I56: 0 | J56: 5.5
A57: BMC22EC018 | B57: - | C57: F | D57: - | E57: - | F57: - | G57: - | H57: - | I57: 1 | J57: 0
A58: LBMC22EC019 | B58: - | C58: F | D58: F | E58: F | F58: F | G58: - | H58: D | I58: 4 | J58: 0
A59: LBMC22EC021 | B59: - | C59: F | D59: F | E59: F | F59: F | G59: - | H59: - | I59: 4 | J59: 0
A64: BATCH - 2023
A65: Register No | B65: ECL331 | C65: ECL333 | D65: ECT301 | E65: ECT303 | F65: ECT305 | G65: ECT307 | H65: HUT300 | I65: MCN301 | J65: Arrears | K65: SGPA
A66: BMC23EC001 | B66: B | C66: B | D66: C | E66: P | F66: B+ | G66: D | H66: P | I66: A+ | J66: 0 | K66: 6.54
A67: BMC23EC002 | B67: B+ | C67: B | D67: F | E67: D | F67: C | G67: F | H67: F | I67: B | J67: 3 | K67: 3.52
A68: BMC23EC003 | B68: A | C68: S | D68: F | E68: P | F68: D | G68: F | H68: P | I68: C+ | J68: 2 | K68: 4.33
A69: BMC23EC004 | B69: C | C69: B+ | D69: F | E69: F | F69: F | G69: F | H69: F | I69: D | J69: 5 | K69: 1.26
A70: BMC23EC005 | B70: FE | C70: FE | D70: FE | E70: FE | F70: FE | G70: FE | H70: FE | I70: FE | J70: 8 | K70: 0
A71: BMC23EC006 | B71: A | C71: S | D71: B | E71: C | F71: B | G71: P | H71: C+ | I71: A+ | J71: 0 | K71: 7.22
A72: BMC23EC007 | B72: A | C72: A+ | D72: C | E72: B+ | F72: A | G72: B | H72: B+ | I72: A+ | J72: 0 | K72: 7.87
A73: BMC23EC008 | B73: C+ | C73: D | D73: F | E73: F | F73: F | G73: F | H73: F | I73: F | J73: 6 | K73: 1.13
A74: BMC23EC009 | B74: B | C74: B | D74: F | E74: F | F74: F | G74: F | H74: F | I74: C | J74: 5 | K74: 1.3
A75: BMC23EC010 | B75: S | C75: S | D75: F | E75: F | F75: P | G75: F | H75: P | I75: C+ | J75: 3 | K75: 3.41
A76: BMC23EC011 | B76: B | C76: A+ | D76: F | E76: P | F76: D | G76: F | H76: C | I76: C | J76: 2 | K76: 4.28
...

Sheet EE
A1: KTU RESULT ANALYZER
A2: BASELIOS MATHEWS II COLLEGE OF ENGINEERING
A3: B.Tech S5 (R, S) Exam Nov 2025 (2019 Scheme) (S5 Result)
A4: Department: EE
A5: 📊 Overall Stats: 29 Students | 13 Regular | 16 Backlog
A7: SUBJECT ANALYTICS DASHBOARD
A8: Select Subject: | B8: Department
A12: Appeared | E12: Passed | I12: Failed | L12: Pass Rate | O12: Fail Rate
A13: =IFERROR(VLOOKUP("EE_" & UPPER($B$8), _DATA_!$A$2:$AZ$62, 2, FALSE), 0) -> 0 | E13: =IFERROR(VLOOKUP("EE_" & UPPER($B$8), _DATA_!$A$2:$AZ$62, 3, FALSE), 0) -> 0 | I13: =IFERROR(VLOOKUP("EE_" & UPPER($B$8), _DATA_!$A$2:$AZ$62, 4, FALSE), 0) -> 0 | L13: =IFERROR(VLOOKUP("EE_" & UPPER($B$8), _DATA_!$A$2:$AZ$62, 5, FALSE), 0) -> 0 | O13: =IFERROR(VLOOKUP("EE_" & UPPER($B$8), _DATA_!$A$2:$AZ$62, 6, FALSE), 0) -> 0
A34: BATCH - 2019
A35: Register No | B35: EET305 | C35: EET307 | D35: Arrears | E35: SGPA
A36: BMC19EE004 | B36: F | C36: - | D36: 1 | E36: 0
A37: BMC19EE005 | B37: - | C37: ABSENT | D37: 1 | E37: 0
A38: BMC19EE009 | B38: F | C38: - | D38: 1 | E38: 0
A43: BATCH - 2020
A44: Register No | B44: EET301 | C44: EET303 | D44: EET305 | E44: Arrears | F44: SGPA
A45: BMC20EE011 | B45: F | C45: F | D45: F | E45: 3 | F45: 0
A46: BMC20EE016 | B46: - | C46: - | D46: ABSENT | E46: 1 | F46: 0
A51: BATCH - 2021
A52: Register No | B52: EET301 | C52: EET303 | D52: EET305 | E52: HUT300 | F52: HUT310 | G52: Arrears | H52: SGPA
A53: BMC21EE004 | B53: - | C53: - | D53: P | E53: - | F53: - | G53: 0 | H53: 5.5
A54: BMC21EE005 | B54: - | C54: F | D54: ABSENT | E54: - | F54: - | G54: 2 | H54: 0
A55: BMC21EE019 | B55: F | C55: - | D55: - | E55: - | F55: F | G55: 2 | H55: 0
A56: BMC21EE024 | B56: - | C56: - | D56: F | E56: - | F56: - | G56: 1 | H56: 0
A57: BMC21EE025 | B57: F | C57: - | D57: - | E57: - | F57: - | G57: 1 | H57: 0
A58: BMC21EE028 | B58: - | C58: - | D58: P | E58: F | F58: C | G58: 1 | H58: 4.36
A63: BATCH - 2022
A64: Register No | B64: EEL331 | C64: EEL333 | D64: EET301 | E64: EET303 | F64: EET305 | G64: EET307 | H64: HUT300 | I64: HUT310 | J64: MCN301 | K64: Arrears | L64: SGPA
A65: BMC22EE001 | B65: F | C65: - | D65: F | E65: F | F65: ABSENT | G65: F | H65: - | I65: - | J65: - | K65: 5 | L65: 0
A66: BMC22EE003 | B66: - | C66: - | D66: F | E66: - | F66: - | G66: F | H66: - | I66: - | J66: - | K66: 2 | L66: 0
A67: BMC22EE005 | B67: - | C67: - | D67: F | E67: ABSENT | F67: - | G67: F | H67: - | I67: ABSENT | J67: - | K67: 4 | L67: 0
A68: BMC22EE007 | B68: - | C68: D | D68: F | E68: - | F68: - | G68: - | H68: - | I68: - | J68: ABSENT | K68: 2 | L68: 2
A69: BMC22EE011 | B69: - | C69: - | D69: F | E69: - | F69: - | G69: - | H69: F | I69: - | J69: - | K69: 2 | L69: 0
A74: BATCH - 2023
A75: Register No | B75: EEL331 | C75: EEL333 | D75: EET301 | E75: EET303 | F75: EET305 | G75: EET307 | H75: HUT300 | I75: MCN301 | J75: Arrears | K75: SGPA
A76: BMC23EE001 | B76: P | C76: P | D76: F | E76: F | F76: F | G76: F | H76: F | I76: C | J76: 5 | K76: 0.96
A77: BMC23EE003 | B77: C | C77: B | D77: F | E77: F | F77: F | G77: F | H77: F | I77: F | J77: 6 | K77: 1.22
A78: BMC23EE004 | B78: A | C78: A | D78: P | E78: C | F78: C | G78: P | H78: P | I78: B+ | J78: 0 | K78: 6.37
A79: BMC23EE005 | B79: A+ | C79: A+ | D79: C+ | E79: A+ | F79: A+ | G79: A | H79: B | I79: B | J79: 0 | K79: 8.37
A80: BMC23EE007 | B80: S | C80: A+ | D80: C+ | E80: A | F80: A | G80: B | H80: C | I80: A | J80: 0 | K80: 7.98
...

Sheet ME
A1: KTU RESULT ANALYZER
A2: BASELIOS MATHEWS II COLLEGE OF ENGINEERING
A3: B.Tech S5 (R, S) Exam Nov 2025 (2019 Scheme) (S5 Result)
A4: Department: ME
A5: 📊 Overall Stats: 34 Students | 14 Regular | 20 Backlog
A7: SUBJECT ANALYTICS DASHBOARD
A8: Select Subject: | B8: Department
A12: Appeared | E12: Passed | I12: Failed | L12: Pass Rate | O12: Fail Rate
A13: =IFERROR(VLOOKUP("ME_" & UPPER($B$8), _DATA_!$A$2:$AZ$62, 2, FALSE), 0) -> 0 | E13: =IFERROR(VLOOKUP("ME_" & UPPER($B$8), _DATA_!$A$2:$AZ$62, 3, FALSE), 0) -> 0 | I13: =IFERROR(VLOOKUP("ME_" & UPPER($B$8), _DATA_!$A$2:$AZ$62, 4, FALSE), 0) -> 0 | L13: =IFERROR(VLOOKUP("ME_" & UPPER($B$8), _DATA_!$A$2:$AZ$62, 5, FALSE), 0) -> 0 | O13: =IFERROR(VLOOKUP("ME_" & UPPER($B$8), _DATA_!$A$2:$AZ$62, 6, FALSE), 0) -> 0
A34: BATCH - 2021
A35: Register No | B35: HUT300 | C35: HUT310 | D35: MCN301 | E35: MET301 | F35: MET303 | G35: MET305 | H35: MET307 | I35: Arrears | J35: SGPA
A36: BMC21ME006 | B36: ABSENT | C36: ABSENT | D36: ABSENT | E36: - | F36: - | G36: ABSENT | H36: ABSENT | I36: 5 | J36: 0
A37: BMC21ME008 | B37: - | C37: ABSENT | D37: P | E37: ABSENT | F37: F | G37: ABSENT | H37: ABSENT | I37: 5 | J37: 0
A38: BMC21ME010 | B38: - | C38: - | D38: - | E38: F | F38: F | G38: F | H38: F | I38: 4 | J38: 0
A39: BMC21ME011 | B39: - | C39: - | D39: - | E39: - | F39: - | G39: - | H39: ABSENT | I39: 1 | J39: 0
A40: BMC21ME013 | B40: - | C40: - | D40: - | E40: F | F40: - | G40: - | H40: F | I40: 2 | J40: 0
A45: BATCH - 2022
A46: Register No | B46: HUT300 | C46: HUT310 | D46: MCN301 | E46: MET301 | F46: MET303 | G46: MET307 | H46: Arrears | I46: SGPA
A47: BMC22ME001 | B47: F | C47: - | D47: - | E47: - | F47: - | G47: F | H47: 2 | I47: 0
A48: BMC22ME002 | B48: F | C48: - | D48: C | E48: C | F48: F | G48: F | H48: 3 | I48: 1.73
A49: BMC22ME003 | B49: F | C49: - | D49: - | E49: F | F49: F | G49: F | H49: 4 | I49: 0
A50: BMC22ME005 | B50: - | C50: - | D50: F | E50: - | F50: - | G50: - | H50: 1 | I50: 0
A51: BMC22ME006 | B51: F | C51: F | D51: P | E51: - | F51: - | G51: - | H51: 2 | I51: 0
A52: BMC22ME007 | B52: - | C52: - | D52: - | E52: - | F52: F | G52: F | H52: 2 | I52: 0
A53: BMC22ME008 | B53: F | C53: - | D53: D | E53: - | F53: - | G53: - | H53: 1 | I53: 0
A54: BMC22ME009 | B54: - | C54: ABSENT | D54: - | E54: - | F54: F | G54: F | H54: 3 | I54: 0
A55: BMC22ME010 | B55: - | C55: - | D55: - | E55: - | F55: F | G55: F | H55: 2 | I55: 0
A56: BMC22ME012 | B56: - | C56: - | D56: F | E56: - | F56: F | G56: F | H56: 3 | I56: 0
A57: BMC22ME013 | B57: F | C57: - | D57: - | E57: - | F57: - | G57: F | H57: 2 | I57: 0
A58: BMC22ME014 | B58: F | C58: - | D58: ABSENT | E58: - | F58: - | G58: F | H58: 3 | I58: 0
... A61: BMC22ME019 | B61: - | C61: ABSENT | D61: - | E61: - | F61: - | G61: F | H61: 2 | I61: 0
A66: BATCH - 2023
A67: Register No | B67: HUT300 | C67: MCN301 | D67: MEL331 | E67: MEL333 | F67: MET301 | G67: MET303 | H67: MET305 | I67: MET307 | J67: Arrears | K67: SGPA
A68: BMC23ME001 | B68: F | C68: D | D68: S | E68: B+ | F68: P | G68: F | H68: P | I68: F | J68: 3 | K68: 3.48
A69: BMC23ME002 | B69: C | C69: B | D69: S | E69: A+ | F69: P | G69: P | H69: C | I69: C | J69: 0 | K69: 6.67
A70: BMC23ME003 | B70: F | C70: C+ | D70: A+ | E70: B+ | F70: F | G70: F | H70: C | I70: F | J70: 4 | K70: 2.61
A71: BMC23ME004 | B71: ABSENT | C71: F | D71: B | E71: C | F71: F | G71: F | H71: F | I71: F | J71: 6 | K71: 1.22
A72: BMC23ME005 | B72: ABSENT | C72: F | D72: B | E72: C | F72: F | G72: ABSENT | H72: F | I72: ABSENT | J72: 6 | K72: 1.22
A73: BMC23ME006 | B73: C | C73: A | D73: S | E73: A | F73: B | G73: P | H73: D | I73: F | J73: 1 | K73: 5.76
A74: BMC23ME008 | B74: D | C74: B | D74: S | E74: S | F74: B+ | G74: C | H74: C | I74: B | J74: 0 | K74: 7.48
...

Sheet _STUDENTS_
A2: AE_AET301 | B2: Failed | C2: BMC19AE004 | D2: -
A3: AE_AET307 | B3: Failed | C3: BMC19AE001 | D3: -
A4: AI_AIL333 | B4: Topper | C4: BMC23AI012 | D4: A+
A5: AI_AIL333 | B5: Topper | C5: BMC23AI014 | D5: A+
A6: AI_AIL333 | B6: Topper | C6: BMC23AI020 | D6: A+
A7: AI_AIL333 | B7: Topper | C7: BMC23AI022 | D7: A+
A8: AI_AIL333 | B8: Topper | C8: BMC23AI029 | D8: A+
A9: AI_AIL333 | B9: Topper | C9: BMC23AI036 | D9: A+
A10: AI_AIL333 | B10: Topper | C10: BMC23AI039 | D10: A+
A11: AI_AIL333 | B11: Topper | C11: BMC23AI043 | D11: A+
A12: AI_AIL333 | B12: Topper | C12: BMC23AI003 | D12: S
A13: AI_AIL333 | B13: Topper | C13: BMC23AI005 | D13: S
... A1117: ME_MET307 | B1117: Failed | C1117: LBMC23ME016 | D1117: -

Sheet _DATA_
A1: Dept_Subject_Key | B1: Appeared | C1: Passed | D1: Failed | E1: Pass_P | F1: Fail_P | G1: S | H1: A+ | I1: A | J1: B+ | K1: B | L1: C+ | M1: C | N1: D | O1: P | P1: PASS | Q1: F | R1: FE | S1: Absent | T1: Withheld
A2: AE_DEPARTMENT | B2: 2 | C2: 0 | D2: 2 | E2: 0 | F2: 100 | G2: 0 | H2: 0 | I2: 0 | J2: 0 | K2: 0 | L2: 0 | M2: 0 | N2: 0 | O2: 0 | P2: 0 | Q2: 1 | R2: 0 | S2: 0 | T2: 0
A3: AE_AET301 | B3: 1 | C3: 0 | D3: 1 | E3: 0 | F3: 100 | G3: 0 | H3: 0 | I3: 0 | J3: 0 | K3: 0 | L3: 0 | M3: 0 | N3: 0 | O3: 0 | P3: 0 | Q3: 1 | R3: 0 | S3: 0 | T3: 0
A4: AE_AET307 | B4: 1 | C4: 0 | D4: 1 | E4: 0 | F4: 100 | G4: 0 | H4: 0 | I4: 0 | J4: 0 | K4: 0 | L4: 0 | M4: 0 | N4: 0 | O4: 0 | P4: 0 | Q4: 0 | R4: 0 | S4: 0 | T4: 0
A5: AI_DEPARTMENT | B5: 42 | C5: 16 | D5: 26 | E5: 38.095238 | F5: 61.904762 | G5: 42 | H5: 26 | I5: 24 | J5: 21 | K5: 22 | L5: 20 | M5: 22 | N5: 33 | O5: 44 | P5: 0 | Q5: 71 | R5: 0 | S5: 0 | T5: 0
A6: AI_AIL333 | B6: 42 | C6: 41 | D6: 1 | E6: 97.619048 | F6: 2.3809524 | G6: 10 | H6: 8 | I6: 5 | J6: 7 | K6: 3 | L6: 1 | M6: 1 | N6: 6 | O6: 0 | P6: 0 | Q6: 0 | R6: 0 | S6: 0 | T6: 0
A7: AI_AIT301 | B7: 42 | C7: 38 | D7: 4 | E7: 90.47619 | F7: 9.5238095 | G7: 0 | H7: 1 | I7: 2 | J7: 3 | K7: 8 | L7: 2 | M7: 8 | N7: 6 | O7: 8 | P7: 0 | Q7: 3 | R7: 0 | S7: 0 | T7: 0
A8: AI_AIT307 | B8: 42 | C8: 33 | D8: 9 | E8: 78.571429 | F8: 21.428571 | G8: 2 | H8: 1 | I8: 4 | J8: 2 | K8: 1 | L8: 4 | M8: 6 | N8: 3 | O8: 10 | P8: 0 | Q8: 8 | R8: 0 | S8: 0 | T8: 0
A9: AI_AML331 | B9: 42 | C9: 41 | D9: 1 | E9: 97.619048 | F9: 2.3809524 | G9: 30 | H9: 10 | I9: 1 | J9: 0 | K9: 0 | L9: 0 | M9: 0 | N9: 0 | O9: 0 | P9: 0 | Q9: 0 | R9: 0 | S9: 0 | T9: 0
A10: AI_AMT305 | B10: 42 | C10: 23 | D10: 19 | E10: 54.761905 | F10: 45.238095 | G10: 0 | H10: 1 | I10: 5 | J10: 2 | K10: 0 | L10: 2 | M10: 3 | N10: 3 | O10: 7 | P10: 0 | Q10: 17 | R10: 0 | S10: 0 | T10: 0
A11: AI_CST303 | B11: 42 | C11: 17 | D11: 25 | E11: 40.47619 | F11: 59.52381 | G11: 0 | H11: 0 | I11: 1 | J11: 1 | K11: 3 | L11: 0 | M11: 0 | N11: 2 | O11: 10 | P11: 0 | Q11: 24 | R11: 0 | S11: 0 | T11: 0
A12: AI_CST309 | B12: 42 | C12: 21 | D12: 21 | E12: 50 | F12: 50 | G12: 0 | H12: 1 | I12: 2 | J12: 2 | K12: 3 | L12: 3 | M12: 0 | N12: 5 | O12: 5 | P12: 0 | Q12: 19 | R12: 0 | S12: 0 | T12: 0
A13: AI_MCN301 | B13: 42 | C13: 40 | D13: 2 | E13: 95.238095 | F13: 4.7619048 | G13: 0 | H13: 4 | I13: 4 | J13: 4 | K13: 4 | L13: 8 | M13: 4 | N13: 8 | O13: 4 | P13: 0 | Q13: 0 | R13: 0 | S13: 0 | T13: 0
... A62: ME_MET307 | B62: 30 | C62: 4 | D62: 26 | E62: 13.333333 | F62: 86.666667 | G62: 0 | H62: 0 | I62: 0 | J62: 0 | K62: 2 | L62: 1 | M62: 1 | N62: 0 | O62: 0 | P62: 0 | Q62: 20 | R62: 0 | S62: 0 | T62: 0
